# Goxel 0.13.0
# One line per voxel
# X Y Z RRGGBB
-16 -16 0 000000
-15 -16 0 ff0000
-14 -16 0 ff0000
-13 -16 0 ff0000
-12 -16 0 ff0000
-11 -16 0 ff0000
-10 -16 0 ff0000
-9 -16 0 ff0000
-8 -16 0 ff0000
-7 -16 0 ff0000
-6 -16 0 ff0000
-5 -16 0 ff0000
-4 -16 0 ff0000
-3 -16 0 ff0000
-2 -16 0 ff0000
-1 -16 0 ff0000
-16 -15 0 66ff00
-15 -15 0 66ff00
-14 -15 0 66ff00
-13 -15 0 66ff00
-12 -15 0 66ff00
-11 -15 0 66ff00
-10 -15 0 66ff00
-9 -15 0 66ff00
-8 -15 0 66ff00
-7 -15 0 66ff00
-6 -15 0 66ff00
-5 -15 0 66ff00
-4 -15 0 66ff00
-3 -15 0 66ff00
-2 -15 0 66ff00
-1 -15 0 66ff00
-16 -14 0 66ff00
-15 -14 0 66ff00
-14 -14 0 66ff00
-13 -14 0 66ff00
-12 -14 0 66ff00
-11 -14 0 66ff00
-10 -14 0 66ff00
-9 -14 0 66ff00
-8 -14 0 66ff00
-7 -14 0 66ff00
-6 -14 0 66ff00
-5 -14 0 66ff00
-4 -14 0 66ff00
-3 -14 0 66ff00
-2 -14 0 66ff00
-1 -14 0 66ff00
-16 -13 0 66ff00
-15 -13 0 66ff00
-14 -13 0 66ff00
-13 -13 0 66ff00
-12 -13 0 66ff00
-11 -13 0 66ff00
-10 -13 0 66ff00
-9 -13 0 66ff00
-8 -13 0 66ff00
-7 -13 0 66ff00
-6 -13 0 66ff00
-5 -13 0 66ff00
-4 -13 0 66ff00
-3 -13 0 66ff00
-2 -13 0 66ff00
-1 -13 0 66ff00
-16 -12 0 66ff00
-15 -12 0 66ff00
-14 -12 0 66ff00
-13 -12 0 66ff00
-12 -12 0 66ff00
-11 -12 0 66ff00
-10 -12 0 66ff00
-9 -12 0 66ff00
-8 -12 0 66ff00
-7 -12 0 66ff00
-6 -12 0 66ff00
-5 -12 0 66ff00
-4 -12 0 66ff00
-3 -12 0 66ff00
-2 -12 0 66ff00
-1 -12 0 66ff00
-16 -11 0 66ff00
-15 -11 0 66ff00
-14 -11 0 66ff00
-13 -11 0 66ff00
-12 -11 0 66ff00
-11 -11 0 66ff00
-10 -11 0 66ff00
-9 -11 0 66ff00
-8 -11 0 66ff00
-7 -11 0 66ff00
-6 -11 0 66ff00
-5 -11 0 66ff00
-4 -11 0 66ff00
-3 -11 0 66ff00
-2 -11 0 66ff00
-1 -11 0 66ff00
-16 -10 0 66ff00
-15 -10 0 66ff00
-14 -10 0 66ff00
-13 -10 0 66ff00
-12 -10 0 66ff00
-11 -10 0 66ff00
-10 -10 0 66ff00
-9 -10 0 66ff00
-8 -10 0 66ff00
-7 -10 0 66ff00
-6 -10 0 66ff00
-5 -10 0 66ff00
-4 -10 0 66ff00
-3 -10 0 66ff00
-2 -10 0 66ff00
-1 -10 0 66ff00
-16 -9 0 66ff00
-15 -9 0 66ff00
-14 -9 0 66ff00
-13 -9 0 66ff00
-12 -9 0 66ff00
-11 -9 0 66ff00
-10 -9 0 66ff00
-9 -9 0 66ff00
-8 -9 0 66ff00
-7 -9 0 66ff00
-6 -9 0 66ff00
-5 -9 0 66ff00
-4 -9 0 66ff00
-3 -9 0 66ff00
-2 -9 0 66ff00
-1 -9 0 66ff00
-16 -8 0 66ff00
-15 -8 0 66ff00
-14 -8 0 66ff00
-13 -8 0 66ff00
-12 -8 0 66ff00
-11 -8 0 66ff00
-10 -8 0 66ff00
-9 -8 0 66ff00
-8 -8 0 66ff00
-7 -8 0 66ff00
-6 -8 0 66ff00
-5 -8 0 66ff00
-4 -8 0 66ff00
-3 -8 0 66ff00
-2 -8 0 66ff00
-1 -8 0 66ff00
-16 -7 0 66ff00
-15 -7 0 66ff00
-14 -7 0 66ff00
-13 -7 0 66ff00
-12 -7 0 66ff00
-11 -7 0 66ff00
-10 -7 0 66ff00
-9 -7 0 66ff00
-8 -7 0 66ff00
-7 -7 0 66ff00
-6 -7 0 66ff00
-5 -7 0 66ff00
-4 -7 0 66ff00
-3 -7 0 66ff00
-2 -7 0 66ff00
-1 -7 0 66ff00
-16 -6 0 66ff00
-15 -6 0 66ff00
-14 -6 0 66ff00
-13 -6 0 66ff00
-12 -6 0 66ff00
-11 -6 0 66ff00
-10 -6 0 66ff00
-9 -6 0 66ff00
-8 -6 0 66ff00
-7 -6 0 66ff00
-6 -6 0 66ff00
-5 -6 0 66ff00
-4 -6 0 66ff00
-3 -6 0 66ff00
-2 -6 0 66ff00
-1 -6 0 66ff00
-16 -5 0 66ff00
-15 -5 0 66ff00
-14 -5 0 66ff00
-13 -5 0 66ff00
-12 -5 0 66ff00
-11 -5 0 66ff00
-10 -5 0 66ff00
-9 -5 0 66ff00
-8 -5 0 66ff00
-7 -5 0 66ff00
-6 -5 0 66ff00
-5 -5 0 66ff00
-4 -5 0 66ff00
-3 -5 0 66ff00
-2 -5 0 66ff00
-1 -5 0 66ff00
-16 -4 0 66ff00
-15 -4 0 66ff00
-14 -4 0 66ff00
-13 -4 0 66ff00
-12 -4 0 66ff00
-11 -4 0 66ff00
-10 -4 0 66ff00
-9 -4 0 66ff00
-8 -4 0 66ff00
-7 -4 0 66ff00
-6 -4 0 66ff00
-5 -4 0 66ff00
-4 -4 0 66ff00
-3 -4 0 66ff00
-2 -4 0 66ff00
-1 -4 0 66ff00
-16 -3 0 66ff00
-15 -3 0 66ff00
-14 -3 0 66ff00
-13 -3 0 66ff00
-12 -3 0 66ff00
-11 -3 0 66ff00
-10 -3 0 66ff00
-9 -3 0 66ff00
-8 -3 0 66ff00
-7 -3 0 66ff00
-6 -3 0 66ff00
-5 -3 0 66ff00
-4 -3 0 66ff00
-3 -3 0 66ff00
-2 -3 0 66ff00
-1 -3 0 66ff00
-16 -2 0 66ff00
-15 -2 0 66ff00
-14 -2 0 66ff00
-13 -2 0 66ff00
-12 -2 0 66ff00
-11 -2 0 66ff00
-10 -2 0 66ff00
-9 -2 0 66ff00
-8 -2 0 66ff00
-7 -2 0 66ff00
-6 -2 0 66ff00
-5 -2 0 66ff00
-4 -2 0 66ff00
-3 -2 0 66ff00
-2 -2 0 66ff00
-1 -2 0 66ff00
-16 -1 0 66ff00
-15 -1 0 66ff00
-14 -1 0 66ff00
-13 -1 0 66ff00
-12 -1 0 66ff00
-11 -1 0 66ff00
-10 -1 0 66ff00
-9 -1 0 66ff00
-8 -1 0 66ff00
-7 -1 0 66ff00
-6 -1 0 66ff00
-5 -1 0 66ff00
-4 -1 0 66ff00
-3 -1 0 66ff00
-2 -1 0 66ff00
-1 -1 0 66ff00
-16 -16 1 0000ff
-16 -15 1 cc00ff
-15 -15 1 cc00ff
-14 -15 1 cc00ff
-13 -15 1 cc00ff
-12 -15 1 cc00ff
-11 -15 1 cc00ff
-10 -15 1 cc00ff
-9 -15 1 cc00ff
-8 -15 1 cc00ff
-7 -15 1 cc00ff
-6 -15 1 cc00ff
-5 -15 1 cc00ff
-4 -15 1 cc00ff
-3 -15 1 cc00ff
-2 -15 1 cc00ff
-1 -15 1 cc00ff
-16 -16 2 0000ff
-16 -15 2 cc00ff
-15 -15 2 cc00ff
-14 -15 2 cc00ff
-13 -15 2 cc00ff
-12 -15 2 cc00ff
-11 -15 2 cc00ff
-10 -15 2 cc00ff
-9 -15 2 cc00ff
-8 -15 2 cc00ff
-7 -15 2 cc00ff
-6 -15 2 cc00ff
-5 -15 2 cc00ff
-4 -15 2 cc00ff
-3 -15 2 cc00ff
-2 -15 2 cc00ff
-1 -15 2 cc00ff
-16 -14 2 cc00ff
-15 -14 2 cc00ff
-14 -14 2 cc00ff
-13 -14 2 cc00ff
-12 -14 2 cc00ff
-11 -14 2 cc00ff
-10 -14 2 cc00ff
-9 -14 2 cc00ff
-8 -14 2 cc00ff
-7 -14 2 cc00ff
-6 -14 2 cc00ff
-5 -14 2 cc00ff
-4 -14 2 cc00ff
-3 -14 2 cc00ff
-2 -14 2 cc00ff
-1 -14 2 cc00ff
-16 -16 3 0000ff
-16 -14 3 cc00ff
-15 -14 3 cc00ff
-14 -14 3 cc00ff
-13 -14 3 cc00ff
-12 -14 3 cc00ff
-11 -14 3 cc00ff
-10 -14 3 cc00ff
-9 -14 3 cc00ff
-8 -14 3 cc00ff
-7 -14 3 cc00ff
-6 -14 3 cc00ff
-5 -14 3 cc00ff
-4 -14 3 cc00ff
-3 -14 3 cc00ff
-2 -14 3 cc00ff
-1 -14 3 cc00ff
-16 -13 3 cc00ff
-15 -13 3 cc00ff
-14 -13 3 cc00ff
-13 -13 3 cc00ff
-12 -13 3 cc00ff
-11 -13 3 cc00ff
-10 -13 3 cc00ff
-9 -13 3 cc00ff
-8 -13 3 cc00ff
-7 -13 3 cc00ff
-6 -13 3 cc00ff
-5 -13 3 cc00ff
-4 -13 3 cc00ff
-3 -13 3 cc00ff
-2 -13 3 cc00ff
-1 -13 3 cc00ff
-16 -16 4 0000ff
-16 -13 4 cc00ff
-15 -13 4 cc00ff
-14 -13 4 cc00ff
-13 -13 4 cc00ff
-12 -13 4 cc00ff
-11 -13 4 cc00ff
-10 -13 4 cc00ff
-9 -13 4 cc00ff
-8 -13 4 cc00ff
-7 -13 4 cc00ff
-6 -13 4 cc00ff
-5 -13 4 cc00ff
-4 -13 4 cc00ff
-3 -13 4 cc00ff
-2 -13 4 cc00ff
-1 -13 4 cc00ff
-16 -12 4 cc00ff
-15 -12 4 cc00ff
-14 -12 4 cc00ff
-13 -12 4 cc00ff
-12 -12 4 cc00ff
-11 -12 4 cc00ff
-10 -12 4 cc00ff
-9 -12 4 cc00ff
-8 -12 4 cc00ff
-7 -12 4 cc00ff
-6 -12 4 cc00ff
-5 -12 4 cc00ff
-4 -12 4 cc00ff
-3 -12 4 cc00ff
-2 -12 4 cc00ff
-1 -12 4 cc00ff
-16 -16 5 0000ff
-16 -12 5 cc00ff
-15 -12 5 cc00ff
-14 -12 5 cc00ff
-13 -12 5 cc00ff
-12 -12 5 cc00ff
-11 -12 5 cc00ff
-10 -12 5 cc00ff
-9 -12 5 cc00ff
-8 -12 5 cc00ff
-7 -12 5 cc00ff
-6 -12 5 cc00ff
-5 -12 5 cc00ff
-4 -12 5 cc00ff
-3 -12 5 cc00ff
-2 -12 5 cc00ff
-1 -12 5 cc00ff
-16 -11 5 cc00ff
-15 -11 5 cc00ff
-14 -11 5 cc00ff
-13 -11 5 cc00ff
-12 -11 5 cc00ff
-11 -11 5 cc00ff
-10 -11 5 cc00ff
-9 -11 5 cc00ff
-8 -11 5 cc00ff
-7 -11 5 cc00ff
-6 -11 5 cc00ff
-5 -11 5 cc00ff
-4 -11 5 cc00ff
-3 -11 5 cc00ff
-2 -11 5 cc00ff
-1 -11 5 cc00ff
-16 -16 6 0000ff
-16 -11 6 cc00ff
-15 -11 6 cc00ff
-14 -11 6 cc00ff
-13 -11 6 cc00ff
-12 -11 6 cc00ff
-11 -11 6 cc00ff
-10 -11 6 cc00ff
-9 -11 6 cc00ff
-8 -11 6 cc00ff
-7 -11 6 cc00ff
-6 -11 6 cc00ff
-5 -11 6 cc00ff
-4 -11 6 cc00ff
-3 -11 6 cc00ff
-2 -11 6 cc00ff
-1 -11 6 cc00ff
-16 -10 6 cc00ff
-15 -10 6 cc00ff
-14 -10 6 cc00ff
-13 -10 6 cc00ff
-12 -10 6 cc00ff
-11 -10 6 cc00ff
-10 -10 6 cc00ff
-9 -10 6 cc00ff
-8 -10 6 cc00ff
-7 -10 6 cc00ff
-6 -10 6 cc00ff
-5 -10 6 cc00ff
-4 -10 6 cc00ff
-3 -10 6 cc00ff
-2 -10 6 cc00ff
-1 -10 6 cc00ff
-16 -16 7 0000ff
-16 -10 7 cc00ff
-15 -10 7 cc00ff
-14 -10 7 cc00ff
-13 -10 7 cc00ff
-12 -10 7 cc00ff
-11 -10 7 cc00ff
-10 -10 7 cc00ff
-9 -10 7 cc00ff
-8 -10 7 cc00ff
-7 -10 7 cc00ff
-6 -10 7 cc00ff
-5 -10 7 cc00ff
-4 -10 7 cc00ff
-3 -10 7 cc00ff
-2 -10 7 cc00ff
-1 -10 7 cc00ff
-16 -9 7 cc00ff
-15 -9 7 cc00ff
-14 -9 7 cc00ff
-13 -9 7 cc00ff
-12 -9 7 cc00ff
-11 -9 7 cc00ff
-10 -9 7 cc00ff
-9 -9 7 cc00ff
-8 -9 7 cc00ff
-7 -9 7 cc00ff
-6 -9 7 cc00ff
-5 -9 7 cc00ff
-4 -9 7 cc00ff
-3 -9 7 cc00ff
-2 -9 7 cc00ff
-1 -9 7 cc00ff
-16 -16 8 0000ff
-16 -9 8 cc00ff
-15 -9 8 cc00ff
-14 -9 8 cc00ff
-13 -9 8 cc00ff
-12 -9 8 cc00ff
-11 -9 8 cc00ff
-10 -9 8 cc00ff
-9 -9 8 cc00ff
-8 -9 8 cc00ff
-7 -9 8 cc00ff
-6 -9 8 cc00ff
-5 -9 8 cc00ff
-4 -9 8 cc00ff
-3 -9 8 cc00ff
-2 -9 8 cc00ff
-1 -9 8 cc00ff
-16 -8 8 cc00ff
-15 -8 8 cc00ff
-14 -8 8 cc00ff
-13 -8 8 cc00ff
-12 -8 8 cc00ff
-11 -8 8 cc00ff
-10 -8 8 cc00ff
-9 -8 8 cc00ff
-8 -8 8 cc00ff
-7 -8 8 cc00ff
-6 -8 8 cc00ff
-5 -8 8 cc00ff
-4 -8 8 cc00ff
-3 -8 8 cc00ff
-2 -8 8 cc00ff
-1 -8 8 cc00ff
-16 -16 9 0000ff
-16 -8 9 cc00ff
-15 -8 9 cc00ff
-14 -8 9 cc00ff
-13 -8 9 cc00ff
-12 -8 9 cc00ff
-11 -8 9 cc00ff
-10 -8 9 cc00ff
-9 -8 9 cc00ff
-8 -8 9 cc00ff
-7 -8 9 cc00ff
-6 -8 9 cc00ff
-5 -8 9 cc00ff
-4 -8 9 cc00ff
-3 -8 9 cc00ff
-2 -8 9 cc00ff
-1 -8 9 cc00ff
-16 -7 9 cc00ff
-15 -7 9 cc00ff
-14 -7 9 cc00ff
-13 -7 9 cc00ff
-12 -7 9 cc00ff
-11 -7 9 cc00ff
-10 -7 9 cc00ff
-9 -7 9 cc00ff
-8 -7 9 cc00ff
-7 -7 9 cc00ff
-6 -7 9 cc00ff
-5 -7 9 cc00ff
-4 -7 9 cc00ff
-3 -7 9 cc00ff
-2 -7 9 cc00ff
-1 -7 9 cc00ff
-16 -16 10 0000ff
-16 -7 10 cc00ff
-15 -7 10 cc00ff
-14 -7 10 cc00ff
-13 -7 10 cc00ff
-12 -7 10 cc00ff
-11 -7 10 cc00ff
-10 -7 10 cc00ff
-9 -7 10 cc00ff
-8 -7 10 cc00ff
-7 -7 10 cc00ff
-6 -7 10 cc00ff
-5 -7 10 cc00ff
-4 -7 10 cc00ff
-3 -7 10 cc00ff
-2 -7 10 cc00ff
-1 -7 10 cc00ff
-16 -6 10 cc00ff
-15 -6 10 cc00ff
-14 -6 10 cc00ff
-13 -6 10 cc00ff
-12 -6 10 cc00ff
-11 -6 10 cc00ff
-10 -6 10 cc00ff
-9 -6 10 cc00ff
-8 -6 10 cc00ff
-7 -6 10 cc00ff
-6 -6 10 cc00ff
-5 -6 10 cc00ff
-4 -6 10 cc00ff
-3 -6 10 cc00ff
-2 -6 10 cc00ff
-1 -6 10 cc00ff
-16 -16 11 0000ff
-16 -6 11 cc00ff
-15 -6 11 cc00ff
-14 -6 11 cc00ff
-13 -6 11 cc00ff
-12 -6 11 cc00ff
-11 -6 11 cc00ff
-10 -6 11 cc00ff
-9 -6 11 cc00ff
-8 -6 11 cc00ff
-7 -6 11 cc00ff
-6 -6 11 cc00ff
-5 -6 11 cc00ff
-4 -6 11 cc00ff
-3 -6 11 cc00ff
-2 -6 11 cc00ff
-1 -6 11 cc00ff
-16 -5 11 cc00ff
-15 -5 11 cc00ff
-14 -5 11 cc00ff
-13 -5 11 cc00ff
-12 -5 11 cc00ff
-11 -5 11 cc00ff
-10 -5 11 cc00ff
-9 -5 11 cc00ff
-8 -5 11 cc00ff
-7 -5 11 cc00ff
-6 -5 11 cc00ff
-5 -5 11 cc00ff
-4 -5 11 cc00ff
-3 -5 11 cc00ff
-2 -5 11 cc00ff
-1 -5 11 cc00ff
-16 -16 12 0000ff
-16 -5 12 cc00ff
-15 -5 12 cc00ff
-14 -5 12 cc00ff
-13 -5 12 cc00ff
-12 -5 12 cc00ff
-11 -5 12 cc00ff
-10 -5 12 cc00ff
-9 -5 12 cc00ff
-8 -5 12 cc00ff
-7 -5 12 cc00ff
-6 -5 12 cc00ff
-5 -5 12 cc00ff
-4 -5 12 cc00ff
-3 -5 12 cc00ff
-2 -5 12 cc00ff
-1 -5 12 cc00ff
-16 -4 12 cc00ff
-15 -4 12 cc00ff
-14 -4 12 cc00ff
-13 -4 12 cc00ff
-12 -4 12 cc00ff
-11 -4 12 cc00ff
-10 -4 12 cc00ff
-9 -4 12 cc00ff
-8 -4 12 cc00ff
-7 -4 12 cc00ff
-6 -4 12 cc00ff
-5 -4 12 cc00ff
-4 -4 12 cc00ff
-3 -4 12 cc00ff
-2 -4 12 cc00ff
-1 -4 12 cc00ff
-16 -16 13 0000ff
-16 -4 13 cc00ff
-15 -4 13 cc00ff
-14 -4 13 cc00ff
-13 -4 13 cc00ff
-12 -4 13 cc00ff
-11 -4 13 cc00ff
-10 -4 13 cc00ff
-9 -4 13 cc00ff
-8 -4 13 cc00ff
-7 -4 13 cc00ff
-6 -4 13 cc00ff
-5 -4 13 cc00ff
-4 -4 13 cc00ff
-3 -4 13 cc00ff
-2 -4 13 cc00ff
-1 -4 13 cc00ff
-16 -3 13 cc00ff
-15 -3 13 cc00ff
-14 -3 13 cc00ff
-13 -3 13 cc00ff
-12 -3 13 cc00ff
-11 -3 13 cc00ff
-10 -3 13 cc00ff
-9 -3 13 cc00ff
-8 -3 13 cc00ff
-7 -3 13 cc00ff
-6 -3 13 cc00ff
-5 -3 13 cc00ff
-4 -3 13 cc00ff
-3 -3 13 cc00ff
-2 -3 13 cc00ff
-1 -3 13 cc00ff
-16 -16 14 0000ff
-16 -3 14 cc00ff
-15 -3 14 cc00ff
-14 -3 14 cc00ff
-13 -3 14 cc00ff
-12 -3 14 cc00ff
-11 -3 14 cc00ff
-10 -3 14 cc00ff
-9 -3 14 cc00ff
-8 -3 14 cc00ff
-7 -3 14 cc00ff
-6 -3 14 cc00ff
-5 -3 14 cc00ff
-4 -3 14 cc00ff
-3 -3 14 cc00ff
-2 -3 14 cc00ff
-1 -3 14 cc00ff
-16 -2 14 cc00ff
-15 -2 14 cc00ff
-14 -2 14 cc00ff
-13 -2 14 cc00ff
-12 -2 14 cc00ff
-11 -2 14 cc00ff
-10 -2 14 cc00ff
-9 -2 14 cc00ff
-8 -2 14 cc00ff
-7 -2 14 cc00ff
-6 -2 14 cc00ff
-5 -2 14 cc00ff
-4 -2 14 cc00ff
-3 -2 14 cc00ff
-2 -2 14 cc00ff
-1 -2 14 cc00ff
-16 -16 15 0000ff
-16 -2 15 cc00ff
-15 -2 15 cc00ff
-14 -2 15 cc00ff
-13 -2 15 cc00ff
-12 -2 15 cc00ff
-11 -2 15 cc00ff
-10 -2 15 cc00ff
-9 -2 15 cc00ff
-8 -2 15 cc00ff
-7 -2 15 cc00ff
-6 -2 15 cc00ff
-5 -2 15 cc00ff
-4 -2 15 cc00ff
-3 -2 15 cc00ff
-2 -2 15 cc00ff
-1 -2 15 cc00ff
-16 -1 15 cc00ff
-15 -1 15 cc00ff
-14 -1 15 cc00ff
-13 -1 15 cc00ff
-12 -1 15 cc00ff
-11 -1 15 cc00ff
-10 -1 15 cc00ff
-9 -1 15 cc00ff
-8 -1 15 cc00ff
-7 -1 15 cc00ff
-6 -1 15 cc00ff
-5 -1 15 cc00ff
-4 -1 15 cc00ff
-3 -1 15 cc00ff
-2 -1 15 cc00ff
-1 -1 15 cc00ff
0 -16 0 ff0000
1 -16 0 ff0000
2 -16 0 ff0000
3 -16 0 ff0000
4 -16 0 ff0000
5 -16 0 ff0000
6 -16 0 ff0000
7 -16 0 ff0000
8 -16 0 ff0000
9 -16 0 ff0000
10 -16 0 ff0000
11 -16 0 ff0000
12 -16 0 ff0000
13 -16 0 ff0000
14 -16 0 ff0000
15 -16 0 000000
0 -15 0 66ff00
1 -15 0 66ff00
2 -15 0 66ff00
3 -15 0 66ff00
4 -15 0 66ff00
5 -15 0 66ff00
6 -15 0 66ff00
7 -15 0 66ff00
8 -15 0 66ff00
9 -15 0 66ff00
10 -15 0 66ff00
11 -15 0 66ff00
12 -15 0 66ff00
13 -15 0 66ff00
14 -15 0 66ff00
15 -15 0 66ff00
0 -14 0 66ff00
1 -14 0 66ff00
2 -14 0 66ff00
3 -14 0 66ff00
4 -14 0 66ff00
5 -14 0 66ff00
6 -14 0 66ff00
7 -14 0 66ff00
8 -14 0 66ff00
9 -14 0 66ff00
10 -14 0 66ff00
11 -14 0 66ff00
12 -14 0 66ff00
13 -14 0 66ff00
14 -14 0 66ff00
15 -14 0 66ff00
0 -13 0 66ff00
1 -13 0 66ff00
2 -13 0 66ff00
3 -13 0 66ff00
4 -13 0 66ff00
5 -13 0 66ff00
6 -13 0 66ff00
7 -13 0 66ff00
8 -13 0 66ff00
9 -13 0 66ff00
10 -13 0 66ff00
11 -13 0 66ff00
12 -13 0 66ff00
13 -13 0 66ff00
14 -13 0 66ff00
15 -13 0 66ff00
0 -12 0 66ff00
1 -12 0 66ff00
2 -12 0 66ff00
3 -12 0 66ff00
4 -12 0 66ff00
5 -12 0 66ff00
6 -12 0 66ff00
7 -12 0 66ff00
8 -12 0 66ff00
9 -12 0 66ff00
10 -12 0 66ff00
11 -12 0 66ff00
12 -12 0 66ff00
13 -12 0 66ff00
14 -12 0 66ff00
15 -12 0 66ff00
0 -11 0 66ff00
1 -11 0 66ff00
2 -11 0 66ff00
3 -11 0 66ff00
4 -11 0 66ff00
5 -11 0 66ff00
6 -11 0 66ff00
7 -11 0 66ff00
8 -11 0 66ff00
9 -11 0 66ff00
10 -11 0 66ff00
11 -11 0 66ff00
12 -11 0 66ff00
13 -11 0 66ff00
14 -11 0 66ff00
15 -11 0 66ff00
0 -10 0 66ff00
1 -10 0 66ff00
2 -10 0 66ff00
3 -10 0 66ff00
4 -10 0 66ff00
5 -10 0 66ff00
6 -10 0 66ff00
7 -10 0 66ff00
8 -10 0 66ff00
9 -10 0 66ff00
10 -10 0 66ff00
11 -10 0 66ff00
12 -10 0 66ff00
13 -10 0 66ff00
14 -10 0 66ff00
15 -10 0 66ff00
0 -9 0 66ff00
1 -9 0 66ff00
2 -9 0 66ff00
3 -9 0 66ff00
4 -9 0 66ff00
5 -9 0 66ff00
6 -9 0 66ff00
7 -9 0 66ff00
8 -9 0 66ff00
9 -9 0 66ff00
10 -9 0 66ff00
11 -9 0 66ff00
12 -9 0 66ff00
13 -9 0 66ff00
14 -9 0 66ff00
15 -9 0 66ff00
0 -8 0 66ff00
1 -8 0 66ff00
2 -8 0 66ff00
3 -8 0 66ff00
4 -8 0 66ff00
5 -8 0 66ff00
6 -8 0 66ff00
7 -8 0 66ff00
8 -8 0 66ff00
9 -8 0 66ff00
10 -8 0 66ff00
11 -8 0 66ff00
12 -8 0 66ff00
13 -8 0 66ff00
14 -8 0 66ff00
15 -8 0 66ff00
0 -7 0 66ff00
1 -7 0 66ff00
2 -7 0 66ff00
3 -7 0 66ff00
4 -7 0 66ff00
5 -7 0 66ff00
6 -7 0 66ff00
7 -7 0 66ff00
8 -7 0 66ff00
9 -7 0 66ff00
10 -7 0 66ff00
11 -7 0 66ff00
12 -7 0 66ff00
13 -7 0 66ff00
14 -7 0 66ff00
15 -7 0 66ff00
0 -6 0 66ff00
1 -6 0 66ff00
2 -6 0 66ff00
3 -6 0 66ff00
4 -6 0 66ff00
5 -6 0 66ff00
6 -6 0 66ff00
7 -6 0 66ff00
8 -6 0 66ff00
9 -6 0 66ff00
10 -6 0 66ff00
11 -6 0 66ff00
12 -6 0 66ff00
13 -6 0 66ff00
14 -6 0 66ff00
15 -6 0 66ff00
0 -5 0 66ff00
1 -5 0 66ff00
2 -5 0 66ff00
3 -5 0 66ff00
4 -5 0 66ff00
5 -5 0 66ff00
6 -5 0 66ff00
7 -5 0 66ff00
8 -5 0 66ff00
9 -5 0 66ff00
10 -5 0 66ff00
11 -5 0 66ff00
12 -5 0 66ff00
13 -5 0 66ff00
14 -5 0 66ff00
15 -5 0 66ff00
0 -4 0 66ff00
1 -4 0 66ff00
2 -4 0 66ff00
3 -4 0 66ff00
4 -4 0 66ff00
5 -4 0 66ff00
6 -4 0 66ff00
7 -4 0 66ff00
8 -4 0 66ff00
9 -4 0 66ff00
10 -4 0 66ff00
11 -4 0 66ff00
12 -4 0 66ff00
13 -4 0 66ff00
14 -4 0 66ff00
15 -4 0 66ff00
0 -3 0 66ff00
1 -3 0 66ff00
2 -3 0 66ff00
3 -3 0 66ff00
4 -3 0 66ff00
5 -3 0 66ff00
6 -3 0 66ff00
7 -3 0 66ff00
8 -3 0 66ff00
9 -3 0 66ff00
10 -3 0 66ff00
11 -3 0 66ff00
12 -3 0 66ff00
13 -3 0 66ff00
14 -3 0 66ff00
15 -3 0 66ff00
0 -2 0 66ff00
1 -2 0 66ff00
2 -2 0 66ff00
3 -2 0 66ff00
4 -2 0 66ff00
5 -2 0 66ff00
6 -2 0 66ff00
7 -2 0 66ff00
8 -2 0 66ff00
9 -2 0 66ff00
10 -2 0 66ff00
11 -2 0 66ff00
12 -2 0 66ff00
13 -2 0 66ff00
14 -2 0 66ff00
15 -2 0 66ff00
0 -1 0 66ff00
1 -1 0 66ff00
2 -1 0 66ff00
3 -1 0 66ff00
4 -1 0 66ff00
5 -1 0 66ff00
6 -1 0 66ff00
7 -1 0 66ff00
8 -1 0 66ff00
9 -1 0 66ff00
10 -1 0 66ff00
11 -1 0 66ff00
12 -1 0 66ff00
13 -1 0 66ff00
14 -1 0 66ff00
15 -1 0 66ff00
15 -16 1 0000ff
0 -15 1 cc00ff
1 -15 1 cc00ff
2 -15 1 cc00ff
3 -15 1 cc00ff
4 -15 1 cc00ff
5 -15 1 cc00ff
6 -15 1 cc00ff
7 -15 1 cc00ff
8 -15 1 cc00ff
9 -15 1 cc00ff
10 -15 1 cc00ff
11 -15 1 cc00ff
12 -15 1 cc00ff
13 -15 1 cc00ff
14 -15 1 cc00ff
15 -15 1 cc00ff
15 -16 2 0000ff
0 -15 2 cc00ff
1 -15 2 cc00ff
2 -15 2 cc00ff
3 -15 2 cc00ff
4 -15 2 cc00ff
5 -15 2 cc00ff
6 -15 2 cc00ff
7 -15 2 cc00ff
8 -15 2 cc00ff
9 -15 2 cc00ff
10 -15 2 cc00ff
11 -15 2 cc00ff
12 -15 2 cc00ff
13 -15 2 cc00ff
14 -15 2 cc00ff
15 -15 2 cc00ff
0 -14 2 cc00ff
1 -14 2 cc00ff
2 -14 2 cc00ff
3 -14 2 cc00ff
4 -14 2 cc00ff
5 -14 2 cc00ff
6 -14 2 cc00ff
7 -14 2 cc00ff
8 -14 2 cc00ff
9 -14 2 cc00ff
10 -14 2 cc00ff
11 -14 2 cc00ff
12 -14 2 cc00ff
13 -14 2 cc00ff
14 -14 2 cc00ff
15 -14 2 cc00ff
15 -16 3 0000ff
0 -14 3 cc00ff
1 -14 3 cc00ff
2 -14 3 cc00ff
3 -14 3 cc00ff
4 -14 3 cc00ff
5 -14 3 cc00ff
6 -14 3 cc00ff
7 -14 3 cc00ff
8 -14 3 cc00ff
9 -14 3 cc00ff
10 -14 3 cc00ff
11 -14 3 cc00ff
12 -14 3 cc00ff
13 -14 3 cc00ff
14 -14 3 cc00ff
15 -14 3 cc00ff
0 -13 3 cc00ff
1 -13 3 cc00ff
2 -13 3 cc00ff
3 -13 3 cc00ff
4 -13 3 cc00ff
5 -13 3 cc00ff
6 -13 3 cc00ff
7 -13 3 cc00ff
8 -13 3 cc00ff
9 -13 3 cc00ff
10 -13 3 cc00ff
11 -13 3 cc00ff
12 -13 3 cc00ff
13 -13 3 cc00ff
14 -13 3 cc00ff
15 -13 3 cc00ff
15 -16 4 0000ff
0 -13 4 cc00ff
1 -13 4 cc00ff
2 -13 4 cc00ff
3 -13 4 cc00ff
4 -13 4 cc00ff
5 -13 4 cc00ff
6 -13 4 cc00ff
7 -13 4 cc00ff
8 -13 4 cc00ff
9 -13 4 cc00ff
10 -13 4 cc00ff
11 -13 4 cc00ff
12 -13 4 cc00ff
13 -13 4 cc00ff
14 -13 4 cc00ff
15 -13 4 cc00ff
0 -12 4 cc00ff
1 -12 4 cc00ff
2 -12 4 cc00ff
3 -12 4 cc00ff
4 -12 4 cc00ff
5 -12 4 cc00ff
6 -12 4 cc00ff
7 -12 4 cc00ff
8 -12 4 cc00ff
9 -12 4 cc00ff
10 -12 4 cc00ff
11 -12 4 cc00ff
12 -12 4 cc00ff
13 -12 4 cc00ff
14 -12 4 cc00ff
15 -12 4 cc00ff
15 -16 5 0000ff
0 -12 5 cc00ff
1 -12 5 cc00ff
2 -12 5 cc00ff
3 -12 5 cc00ff
4 -12 5 cc00ff
5 -12 5 cc00ff
6 -12 5 cc00ff
7 -12 5 cc00ff
8 -12 5 cc00ff
9 -12 5 cc00ff
10 -12 5 cc00ff
11 -12 5 cc00ff
12 -12 5 cc00ff
13 -12 5 cc00ff
14 -12 5 cc00ff
15 -12 5 cc00ff
0 -11 5 cc00ff
1 -11 5 cc00ff
2 -11 5 cc00ff
3 -11 5 cc00ff
4 -11 5 cc00ff
5 -11 5 cc00ff
6 -11 5 cc00ff
7 -11 5 cc00ff
8 -11 5 cc00ff
9 -11 5 cc00ff
10 -11 5 cc00ff
11 -11 5 cc00ff
12 -11 5 cc00ff
13 -11 5 cc00ff
14 -11 5 cc00ff
15 -11 5 cc00ff
15 -16 6 0000ff
0 -11 6 cc00ff
1 -11 6 cc00ff
2 -11 6 cc00ff
3 -11 6 cc00ff
4 -11 6 cc00ff
5 -11 6 cc00ff
6 -11 6 cc00ff
7 -11 6 cc00ff
8 -11 6 cc00ff
9 -11 6 cc00ff
10 -11 6 cc00ff
11 -11 6 cc00ff
12 -11 6 cc00ff
13 -11 6 cc00ff
14 -11 6 cc00ff
15 -11 6 cc00ff
0 -10 6 cc00ff
1 -10 6 cc00ff
2 -10 6 cc00ff
3 -10 6 cc00ff
4 -10 6 cc00ff
5 -10 6 cc00ff
6 -10 6 cc00ff
7 -10 6 cc00ff
8 -10 6 cc00ff
9 -10 6 cc00ff
10 -10 6 cc00ff
11 -10 6 cc00ff
12 -10 6 cc00ff
13 -10 6 cc00ff
14 -10 6 cc00ff
15 -10 6 cc00ff
15 -16 7 0000ff
0 -10 7 cc00ff
1 -10 7 cc00ff
2 -10 7 cc00ff
3 -10 7 cc00ff
4 -10 7 cc00ff
5 -10 7 cc00ff
6 -10 7 cc00ff
7 -10 7 cc00ff
8 -10 7 cc00ff
9 -10 7 cc00ff
10 -10 7 cc00ff
11 -10 7 cc00ff
12 -10 7 cc00ff
13 -10 7 cc00ff
14 -10 7 cc00ff
15 -10 7 cc00ff
0 -9 7 cc00ff
1 -9 7 cc00ff
2 -9 7 cc00ff
3 -9 7 cc00ff
4 -9 7 cc00ff
5 -9 7 cc00ff
6 -9 7 cc00ff
7 -9 7 cc00ff
8 -9 7 cc00ff
9 -9 7 cc00ff
10 -9 7 cc00ff
11 -9 7 cc00ff
12 -9 7 cc00ff
13 -9 7 cc00ff
14 -9 7 cc00ff
15 -9 7 cc00ff
15 -16 8 0000ff
0 -9 8 cc00ff
1 -9 8 cc00ff
2 -9 8 cc00ff
3 -9 8 cc00ff
4 -9 8 cc00ff
5 -9 8 cc00ff
6 -9 8 cc00ff
7 -9 8 cc00ff
8 -9 8 cc00ff
9 -9 8 cc00ff
10 -9 8 cc00ff
11 -9 8 cc00ff
12 -9 8 cc00ff
13 -9 8 cc00ff
14 -9 8 cc00ff
15 -9 8 cc00ff
0 -8 8 cc00ff
1 -8 8 cc00ff
2 -8 8 cc00ff
3 -8 8 cc00ff
4 -8 8 cc00ff
5 -8 8 cc00ff
6 -8 8 cc00ff
7 -8 8 cc00ff
8 -8 8 cc00ff
9 -8 8 cc00ff
10 -8 8 cc00ff
11 -8 8 cc00ff
12 -8 8 cc00ff
13 -8 8 cc00ff
14 -8 8 cc00ff
15 -8 8 cc00ff
15 -16 9 0000ff
0 -8 9 cc00ff
1 -8 9 cc00ff
2 -8 9 cc00ff
3 -8 9 cc00ff
4 -8 9 cc00ff
5 -8 9 cc00ff
6 -8 9 cc00ff
7 -8 9 cc00ff
8 -8 9 cc00ff
9 -8 9 cc00ff
10 -8 9 cc00ff
11 -8 9 cc00ff
12 -8 9 cc00ff
13 -8 9 cc00ff
14 -8 9 cc00ff
15 -8 9 cc00ff
0 -7 9 cc00ff
1 -7 9 cc00ff
2 -7 9 cc00ff
3 -7 9 cc00ff
4 -7 9 cc00ff
5 -7 9 cc00ff
6 -7 9 cc00ff
7 -7 9 cc00ff
8 -7 9 cc00ff
9 -7 9 cc00ff
10 -7 9 cc00ff
11 -7 9 cc00ff
12 -7 9 cc00ff
13 -7 9 cc00ff
14 -7 9 cc00ff
15 -7 9 cc00ff
15 -16 10 0000ff
0 -7 10 cc00ff
1 -7 10 cc00ff
2 -7 10 cc00ff
3 -7 10 cc00ff
4 -7 10 cc00ff
5 -7 10 cc00ff
6 -7 10 cc00ff
7 -7 10 cc00ff
8 -7 10 cc00ff
9 -7 10 cc00ff
10 -7 10 cc00ff
11 -7 10 cc00ff
12 -7 10 cc00ff
13 -7 10 cc00ff
14 -7 10 cc00ff
15 -7 10 cc00ff
0 -6 10 cc00ff
1 -6 10 cc00ff
2 -6 10 cc00ff
3 -6 10 cc00ff
4 -6 10 cc00ff
5 -6 10 cc00ff
6 -6 10 cc00ff
7 -6 10 cc00ff
8 -6 10 cc00ff
9 -6 10 cc00ff
10 -6 10 cc00ff
11 -6 10 cc00ff
12 -6 10 cc00ff
13 -6 10 cc00ff
14 -6 10 cc00ff
15 -6 10 cc00ff
15 -16 11 0000ff
0 -6 11 cc00ff
1 -6 11 cc00ff
2 -6 11 cc00ff
3 -6 11 cc00ff
4 -6 11 cc00ff
5 -6 11 cc00ff
6 -6 11 cc00ff
7 -6 11 cc00ff
8 -6 11 cc00ff
9 -6 11 cc00ff
10 -6 11 cc00ff
11 -6 11 cc00ff
12 -6 11 cc00ff
13 -6 11 cc00ff
14 -6 11 cc00ff
15 -6 11 cc00ff
0 -5 11 cc00ff
1 -5 11 cc00ff
2 -5 11 cc00ff
3 -5 11 cc00ff
4 -5 11 cc00ff
5 -5 11 cc00ff
6 -5 11 cc00ff
7 -5 11 cc00ff
8 -5 11 cc00ff
9 -5 11 cc00ff
10 -5 11 cc00ff
11 -5 11 cc00ff
12 -5 11 cc00ff
13 -5 11 cc00ff
14 -5 11 cc00ff
15 -5 11 cc00ff
15 -16 12 0000ff
0 -5 12 cc00ff
1 -5 12 cc00ff
2 -5 12 cc00ff
3 -5 12 cc00ff
4 -5 12 cc00ff
5 -5 12 cc00ff
6 -5 12 cc00ff
7 -5 12 cc00ff
8 -5 12 cc00ff
9 -5 12 cc00ff
10 -5 12 cc00ff
11 -5 12 cc00ff
12 -5 12 cc00ff
13 -5 12 cc00ff
14 -5 12 cc00ff
15 -5 12 cc00ff
0 -4 12 cc00ff
1 -4 12 cc00ff
2 -4 12 cc00ff
3 -4 12 cc00ff
4 -4 12 cc00ff
5 -4 12 cc00ff
6 -4 12 cc00ff
7 -4 12 cc00ff
8 -4 12 cc00ff
9 -4 12 cc00ff
10 -4 12 cc00ff
11 -4 12 cc00ff
12 -4 12 cc00ff
13 -4 12 cc00ff
14 -4 12 cc00ff
15 -4 12 cc00ff
15 -16 13 0000ff
0 -4 13 cc00ff
1 -4 13 cc00ff
2 -4 13 cc00ff
3 -4 13 cc00ff
4 -4 13 cc00ff
5 -4 13 cc00ff
6 -4 13 cc00ff
7 -4 13 cc00ff
8 -4 13 cc00ff
9 -4 13 cc00ff
10 -4 13 cc00ff
11 -4 13 cc00ff
12 -4 13 cc00ff
13 -4 13 cc00ff
14 -4 13 cc00ff
15 -4 13 cc00ff
0 -3 13 cc00ff
1 -3 13 cc00ff
2 -3 13 cc00ff
3 -3 13 cc00ff
4 -3 13 cc00ff
5 -3 13 cc00ff
6 -3 13 cc00ff
7 -3 13 cc00ff
8 -3 13 cc00ff
9 -3 13 cc00ff
10 -3 13 cc00ff
11 -3 13 cc00ff
12 -3 13 cc00ff
13 -3 13 cc00ff
14 -3 13 cc00ff
15 -3 13 cc00ff
15 -16 14 0000ff
0 -3 14 cc00ff
1 -3 14 cc00ff
2 -3 14 cc00ff
3 -3 14 cc00ff
4 -3 14 cc00ff
5 -3 14 cc00ff
6 -3 14 cc00ff
7 -3 14 cc00ff
8 -3 14 cc00ff
9 -3 14 cc00ff
10 -3 14 cc00ff
11 -3 14 cc00ff
12 -3 14 cc00ff
13 -3 14 cc00ff
14 -3 14 cc00ff
15 -3 14 cc00ff
0 -2 14 cc00ff
1 -2 14 cc00ff
2 -2 14 cc00ff
3 -2 14 cc00ff
4 -2 14 cc00ff
5 -2 14 cc00ff
6 -2 14 cc00ff
7 -2 14 cc00ff
8 -2 14 cc00ff
9 -2 14 cc00ff
10 -2 14 cc00ff
11 -2 14 cc00ff
12 -2 14 cc00ff
13 -2 14 cc00ff
14 -2 14 cc00ff
15 -2 14 cc00ff
15 -16 15 0000ff
0 -2 15 cc00ff
1 -2 15 cc00ff
2 -2 15 cc00ff
3 -2 15 cc00ff
4 -2 15 cc00ff
5 -2 15 cc00ff
6 -2 15 cc00ff
7 -2 15 cc00ff
8 -2 15 cc00ff
9 -2 15 cc00ff
10 -2 15 cc00ff
11 -2 15 cc00ff
12 -2 15 cc00ff
13 -2 15 cc00ff
14 -2 15 cc00ff
15 -2 15 cc00ff
0 -1 15 cc00ff
1 -1 15 cc00ff
2 -1 15 cc00ff
3 -1 15 cc00ff
4 -1 15 cc00ff
5 -1 15 cc00ff
6 -1 15 cc00ff
7 -1 15 cc00ff
8 -1 15 cc00ff
9 -1 15 cc00ff
10 -1 15 cc00ff
11 -1 15 cc00ff
12 -1 15 cc00ff
13 -1 15 cc00ff
14 -1 15 cc00ff
15 -1 15 cc00ff
-16 0 0 66ff00
-15 0 0 66ff00
-14 0 0 66ff00
-13 0 0 66ff00
-12 0 0 66ff00
-11 0 0 66ff00
-10 0 0 66ff00
-9 0 0 66ff00
-8 0 0 66ff00
-7 0 0 66ff00
-6 0 0 66ff00
-5 0 0 66ff00
-4 0 0 66ff00
-3 0 0 66ff00
-2 0 0 66ff00
-1 0 0 66ff00
-16 1 0 66ff00
-15 1 0 66ff00
-14 1 0 66ff00
-13 1 0 66ff00
-12 1 0 66ff00
-11 1 0 66ff00
-10 1 0 66ff00
-9 1 0 66ff00
-8 1 0 66ff00
-7 1 0 66ff00
-6 1 0 66ff00
-5 1 0 66ff00
-4 1 0 66ff00
-3 1 0 66ff00
-2 1 0 66ff00
-1 1 0 66ff00
-16 2 0 66ff00
-15 2 0 66ff00
-14 2 0 66ff00
-13 2 0 66ff00
-12 2 0 66ff00
-11 2 0 66ff00
-10 2 0 66ff00
-9 2 0 66ff00
-8 2 0 66ff00
-7 2 0 66ff00
-6 2 0 66ff00
-5 2 0 66ff00
-4 2 0 66ff00
-3 2 0 66ff00
-2 2 0 66ff00
-1 2 0 66ff00
-16 3 0 66ff00
-15 3 0 66ff00
-14 3 0 66ff00
-13 3 0 66ff00
-12 3 0 66ff00
-11 3 0 66ff00
-10 3 0 66ff00
-9 3 0 66ff00
-8 3 0 66ff00
-7 3 0 66ff00
-6 3 0 66ff00
-5 3 0 66ff00
-4 3 0 66ff00
-3 3 0 66ff00
-2 3 0 66ff00
-1 3 0 66ff00
-16 4 0 66ff00
-15 4 0 66ff00
-14 4 0 66ff00
-13 4 0 66ff00
-12 4 0 66ff00
-11 4 0 66ff00
-10 4 0 66ff00
-9 4 0 66ff00
-8 4 0 66ff00
-7 4 0 66ff00
-6 4 0 66ff00
-5 4 0 66ff00
-4 4 0 66ff00
-3 4 0 66ff00
-2 4 0 66ff00
-1 4 0 66ff00
-16 5 0 66ff00
-15 5 0 66ff00
-14 5 0 66ff00
-13 5 0 66ff00
-12 5 0 66ff00
-11 5 0 66ff00
-10 5 0 66ff00
-9 5 0 66ff00
-8 5 0 66ff00
-7 5 0 66ff00
-6 5 0 66ff00
-5 5 0 66ff00
-4 5 0 66ff00
-3 5 0 66ff00
-2 5 0 66ff00
-1 5 0 66ff00
-16 6 0 66ff00
-15 6 0 66ff00
-14 6 0 66ff00
-13 6 0 66ff00
-12 6 0 66ff00
-11 6 0 66ff00
-10 6 0 66ff00
-9 6 0 66ff00
-8 6 0 66ff00
-7 6 0 66ff00
-6 6 0 66ff00
-5 6 0 66ff00
-4 6 0 66ff00
-3 6 0 66ff00
-2 6 0 66ff00
-1 6 0 66ff00
-16 7 0 66ff00
-15 7 0 66ff00
-14 7 0 66ff00
-13 7 0 66ff00
-12 7 0 66ff00
-11 7 0 66ff00
-10 7 0 66ff00
-9 7 0 66ff00
-8 7 0 66ff00
-7 7 0 66ff00
-6 7 0 66ff00
-5 7 0 66ff00
-4 7 0 66ff00
-3 7 0 66ff00
-2 7 0 66ff00
-1 7 0 66ff00
-16 8 0 66ff00
-15 8 0 66ff00
-14 8 0 66ff00
-13 8 0 66ff00
-12 8 0 66ff00
-11 8 0 66ff00
-10 8 0 66ff00
-9 8 0 66ff00
-8 8 0 66ff00
-7 8 0 66ff00
-6 8 0 66ff00
-5 8 0 66ff00
-4 8 0 66ff00
-3 8 0 66ff00
-2 8 0 66ff00
-1 8 0 66ff00
-16 9 0 66ff00
-15 9 0 66ff00
-14 9 0 66ff00
-13 9 0 66ff00
-12 9 0 66ff00
-11 9 0 66ff00
-10 9 0 66ff00
-9 9 0 66ff00
-8 9 0 66ff00
-7 9 0 66ff00
-6 9 0 66ff00
-5 9 0 66ff00
-4 9 0 66ff00
-3 9 0 66ff00
-2 9 0 66ff00
-1 9 0 66ff00
-16 10 0 66ff00
-15 10 0 66ff00
-14 10 0 66ff00
-13 10 0 66ff00
-12 10 0 66ff00
-11 10 0 66ff00
-10 10 0 66ff00
-9 10 0 66ff00
-8 10 0 66ff00
-7 10 0 66ff00
-6 10 0 66ff00
-5 10 0 66ff00
-4 10 0 66ff00
-3 10 0 66ff00
-2 10 0 66ff00
-1 10 0 66ff00
-16 11 0 66ff00
-15 11 0 66ff00
-14 11 0 66ff00
-13 11 0 66ff00
-12 11 0 66ff00
-11 11 0 66ff00
-10 11 0 66ff00
-9 11 0 66ff00
-8 11 0 66ff00
-7 11 0 66ff00
-6 11 0 66ff00
-5 11 0 66ff00
-4 11 0 66ff00
-3 11 0 66ff00
-2 11 0 66ff00
-1 11 0 66ff00
-16 12 0 66ff00
-15 12 0 66ff00
-14 12 0 66ff00
-13 12 0 66ff00
-12 12 0 66ff00
-11 12 0 66ff00
-10 12 0 66ff00
-9 12 0 66ff00
-8 12 0 66ff00
-7 12 0 66ff00
-6 12 0 66ff00
-5 12 0 66ff00
-4 12 0 66ff00
-3 12 0 66ff00
-2 12 0 66ff00
-1 12 0 66ff00
-16 13 0 66ff00
-15 13 0 66ff00
-14 13 0 66ff00
-13 13 0 66ff00
-12 13 0 66ff00
-11 13 0 66ff00
-10 13 0 66ff00
-9 13 0 66ff00
-8 13 0 66ff00
-7 13 0 66ff00
-6 13 0 66ff00
-5 13 0 66ff00
-4 13 0 66ff00
-3 13 0 66ff00
-2 13 0 66ff00
-1 13 0 66ff00
-16 14 0 66ff00
-15 14 0 66ff00
-14 14 0 66ff00
-13 14 0 66ff00
-12 14 0 66ff00
-11 14 0 66ff00
-10 14 0 66ff00
-9 14 0 66ff00
-8 14 0 66ff00
-7 14 0 66ff00
-6 14 0 66ff00
-5 14 0 66ff00
-4 14 0 66ff00
-3 14 0 66ff00
-2 14 0 66ff00
-1 14 0 66ff00
-16 15 0 000000
-15 15 0 ff0000
-14 15 0 ff0000
-13 15 0 ff0000
-12 15 0 ff0000
-11 15 0 ff0000
-10 15 0 ff0000
-9 15 0 ff0000
-8 15 0 ff0000
-7 15 0 ff0000
-6 15 0 ff0000
-5 15 0 ff0000
-4 15 0 ff0000
-3 15 0 ff0000
-2 15 0 ff0000
-1 15 0 ff0000
-16 15 1 0000ff
-16 15 2 0000ff
-16 15 3 0000ff
-16 15 4 0000ff
-16 15 5 0000ff
-16 15 6 0000ff
-16 15 7 0000ff
-16 15 8 0000ff
-16 15 9 0000ff
-16 15 10 0000ff
-16 15 11 0000ff
-16 15 12 0000ff
-16 15 13 0000ff
-16 15 14 0000ff
-16 15 15 0000ff
0 0 0 66ff00
1 0 0 66ff00
2 0 0 66ff00
3 0 0 66ff00
4 0 0 66ff00
5 0 0 66ff00
6 0 0 66ff00
7 0 0 66ff00
8 0 0 66ff00
9 0 0 66ff00
10 0 0 66ff00
11 0 0 66ff00
12 0 0 66ff00
13 0 0 66ff00
14 0 0 66ff00
15 0 0 66ff00
0 1 0 66ff00
1 1 0 66ff00
2 1 0 66ff00
3 1 0 66ff00
4 1 0 66ff00
5 1 0 66ff00
6 1 0 66ff00
7 1 0 66ff00
8 1 0 66ff00
9 1 0 66ff00
10 1 0 66ff00
11 1 0 66ff00
12 1 0 66ff00
13 1 0 66ff00
14 1 0 66ff00
15 1 0 66ff00
0 2 0 66ff00
1 2 0 66ff00
2 2 0 66ff00
3 2 0 66ff00
4 2 0 66ff00
5 2 0 66ff00
6 2 0 66ff00
7 2 0 66ff00
8 2 0 66ff00
9 2 0 66ff00
10 2 0 66ff00
11 2 0 66ff00
12 2 0 66ff00
13 2 0 66ff00
14 2 0 66ff00
15 2 0 66ff00
0 3 0 66ff00
1 3 0 66ff00
2 3 0 66ff00
3 3 0 66ff00
4 3 0 66ff00
5 3 0 66ff00
6 3 0 66ff00
7 3 0 66ff00
8 3 0 66ff00
9 3 0 66ff00
10 3 0 66ff00
11 3 0 66ff00
12 3 0 66ff00
13 3 0 66ff00
14 3 0 66ff00
15 3 0 66ff00
0 4 0 66ff00
1 4 0 66ff00
2 4 0 66ff00
3 4 0 66ff00
4 4 0 66ff00
5 4 0 66ff00
6 4 0 66ff00
7 4 0 66ff00
8 4 0 66ff00
9 4 0 66ff00
10 4 0 66ff00
11 4 0 66ff00
12 4 0 66ff00
13 4 0 66ff00
14 4 0 66ff00
15 4 0 66ff00
0 5 0 66ff00
1 5 0 66ff00
2 5 0 66ff00
3 5 0 66ff00
4 5 0 66ff00
5 5 0 66ff00
6 5 0 66ff00
7 5 0 66ff00
8 5 0 66ff00
9 5 0 66ff00
10 5 0 66ff00
11 5 0 66ff00
12 5 0 66ff00
13 5 0 66ff00
14 5 0 66ff00
15 5 0 66ff00
0 6 0 66ff00
1 6 0 66ff00
2 6 0 66ff00
3 6 0 66ff00
4 6 0 66ff00
5 6 0 66ff00
6 6 0 66ff00
7 6 0 66ff00
8 6 0 66ff00
9 6 0 66ff00
10 6 0 66ff00
11 6 0 66ff00
12 6 0 66ff00
13 6 0 66ff00
14 6 0 66ff00
15 6 0 66ff00
0 7 0 66ff00
1 7 0 66ff00
2 7 0 66ff00
3 7 0 66ff00
4 7 0 66ff00
5 7 0 66ff00
6 7 0 66ff00
7 7 0 66ff00
8 7 0 66ff00
9 7 0 66ff00
10 7 0 66ff00
11 7 0 66ff00
12 7 0 66ff00
13 7 0 66ff00
14 7 0 66ff00
15 7 0 66ff00
0 8 0 66ff00
1 8 0 66ff00
2 8 0 66ff00
3 8 0 66ff00
4 8 0 66ff00
5 8 0 66ff00
6 8 0 66ff00
7 8 0 66ff00
8 8 0 66ff00
9 8 0 66ff00
10 8 0 66ff00
11 8 0 66ff00
12 8 0 66ff00
13 8 0 66ff00
14 8 0 66ff00
15 8 0 66ff00
0 9 0 66ff00
1 9 0 66ff00
2 9 0 66ff00
3 9 0 66ff00
4 9 0 66ff00
5 9 0 66ff00
6 9 0 66ff00
7 9 0 66ff00
8 9 0 66ff00
9 9 0 66ff00
10 9 0 66ff00
11 9 0 66ff00
12 9 0 66ff00
13 9 0 66ff00
14 9 0 66ff00
15 9 0 66ff00
0 10 0 66ff00
1 10 0 66ff00
2 10 0 66ff00
3 10 0 66ff00
4 10 0 66ff00
5 10 0 66ff00
6 10 0 66ff00
7 10 0 66ff00
8 10 0 66ff00
9 10 0 66ff00
10 10 0 66ff00
11 10 0 66ff00
12 10 0 66ff00
13 10 0 66ff00
14 10 0 66ff00
15 10 0 66ff00
0 11 0 66ff00
1 11 0 66ff00
2 11 0 66ff00
3 11 0 66ff00
4 11 0 66ff00
5 11 0 66ff00
6 11 0 66ff00
7 11 0 66ff00
8 11 0 66ff00
9 11 0 66ff00
10 11 0 66ff00
11 11 0 66ff00
12 11 0 66ff00
13 11 0 66ff00
14 11 0 66ff00
15 11 0 66ff00
0 12 0 66ff00
1 12 0 66ff00
2 12 0 66ff00
3 12 0 66ff00
4 12 0 66ff00
5 12 0 66ff00
6 12 0 66ff00
7 12 0 66ff00
8 12 0 66ff00
9 12 0 66ff00
10 12 0 66ff00
11 12 0 66ff00
12 12 0 66ff00
13 12 0 66ff00
14 12 0 66ff00
15 12 0 66ff00
0 13 0 66ff00
1 13 0 66ff00
2 13 0 66ff00
3 13 0 66ff00
4 13 0 66ff00
5 13 0 66ff00
6 13 0 66ff00
7 13 0 66ff00
8 13 0 66ff00
9 13 0 66ff00
10 13 0 66ff00
11 13 0 66ff00
12 13 0 66ff00
13 13 0 66ff00
14 13 0 66ff00
15 13 0 66ff00
0 14 0 66ff00
1 14 0 66ff00
2 14 0 66ff00
3 14 0 66ff00
4 14 0 66ff00
5 14 0 66ff00
6 14 0 66ff00
7 14 0 66ff00
8 14 0 66ff00
9 14 0 66ff00
10 14 0 66ff00
11 14 0 66ff00
12 14 0 66ff00
13 14 0 66ff00
14 14 0 66ff00
15 14 0 66ff00
0 15 0 ff0000
1 15 0 ff0000
2 15 0 ff0000
3 15 0 ff0000
4 15 0 ff0000
5 15 0 ff0000
6 15 0 ff0000
7 15 0 ff0000
8 15 0 ff0000
9 15 0 ff0000
10 15 0 ff0000
11 15 0 ff0000
12 15 0 ff0000
13 15 0 ff0000
14 15 0 ff0000
15 15 0 000000
15 15 1 0000ff
15 15 2 0000ff
15 15 3 0000ff
15 15 4 0000ff
15 15 5 0000ff
15 15 6 0000ff
15 15 7 0000ff
15 15 8 0000ff
15 15 9 0000ff
15 15 10 0000ff
15 15 11 0000ff
15 15 12 0000ff
15 15 13 0000ff
15 15 14 0000ff
15 15 15 0000ff
-16 0 16 cc00ff
-15 0 16 cc00ff
-14 0 16 cc00ff
-13 0 16 cc00ff
-12 0 16 cc00ff
-11 0 16 cc00ff
-10 0 16 cc00ff
-9 0 16 cc00ff
-8 0 16 cc00ff
-7 0 16 cc00ff
-6 0 16 cc00ff
-5 0 16 cc00ff
-4 0 16 cc00ff
-3 0 16 cc00ff
-2 0 16 cc00ff
-1 0 16 cc00ff
-16 15 16 0000ff
-16 0 17 cc00ff
-15 0 17 cc00ff
-14 0 17 cc00ff
-13 0 17 cc00ff
-12 0 17 cc00ff
-11 0 17 cc00ff
-10 0 17 cc00ff
-9 0 17 cc00ff
-8 0 17 cc00ff
-7 0 17 cc00ff
-6 0 17 cc00ff
-5 0 17 cc00ff
-4 0 17 cc00ff
-3 0 17 cc00ff
-2 0 17 cc00ff
-1 0 17 cc00ff
-16 1 17 cc00ff
-15 1 17 cc00ff
-14 1 17 cc00ff
-13 1 17 cc00ff
-12 1 17 cc00ff
-11 1 17 cc00ff
-10 1 17 cc00ff
-9 1 17 cc00ff
-8 1 17 cc00ff
-7 1 17 cc00ff
-6 1 17 cc00ff
-5 1 17 cc00ff
-4 1 17 cc00ff
-3 1 17 cc00ff
-2 1 17 cc00ff
-1 1 17 cc00ff
-16 15 17 0000ff
-16 1 18 cc00ff
-15 1 18 cc00ff
-14 1 18 cc00ff
-13 1 18 cc00ff
-12 1 18 cc00ff
-11 1 18 cc00ff
-10 1 18 cc00ff
-9 1 18 cc00ff
-8 1 18 cc00ff
-7 1 18 cc00ff
-6 1 18 cc00ff
-5 1 18 cc00ff
-4 1 18 cc00ff
-3 1 18 cc00ff
-2 1 18 cc00ff
-1 1 18 cc00ff
-16 2 18 cc00ff
-15 2 18 cc00ff
-14 2 18 cc00ff
-13 2 18 cc00ff
-12 2 18 cc00ff
-11 2 18 cc00ff
-10 2 18 cc00ff
-9 2 18 cc00ff
-8 2 18 cc00ff
-7 2 18 cc00ff
-6 2 18 cc00ff
-5 2 18 cc00ff
-4 2 18 cc00ff
-3 2 18 cc00ff
-2 2 18 cc00ff
-1 2 18 cc00ff
-16 15 18 0000ff
-16 2 19 cc00ff
-15 2 19 cc00ff
-14 2 19 cc00ff
-13 2 19 cc00ff
-12 2 19 cc00ff
-11 2 19 cc00ff
-10 2 19 cc00ff
-9 2 19 cc00ff
-8 2 19 cc00ff
-7 2 19 cc00ff
-6 2 19 cc00ff
-5 2 19 cc00ff
-4 2 19 cc00ff
-3 2 19 cc00ff
-2 2 19 cc00ff
-1 2 19 cc00ff
-16 3 19 cc00ff
-15 3 19 cc00ff
-14 3 19 cc00ff
-13 3 19 cc00ff
-12 3 19 cc00ff
-11 3 19 cc00ff
-10 3 19 cc00ff
-9 3 19 cc00ff
-8 3 19 cc00ff
-7 3 19 cc00ff
-6 3 19 cc00ff
-5 3 19 cc00ff
-4 3 19 cc00ff
-3 3 19 cc00ff
-2 3 19 cc00ff
-1 3 19 cc00ff
-16 15 19 0000ff
-16 3 20 cc00ff
-15 3 20 cc00ff
-14 3 20 cc00ff
-13 3 20 cc00ff
-12 3 20 cc00ff
-11 3 20 cc00ff
-10 3 20 cc00ff
-9 3 20 cc00ff
-8 3 20 cc00ff
-7 3 20 cc00ff
-6 3 20 cc00ff
-5 3 20 cc00ff
-4 3 20 cc00ff
-3 3 20 cc00ff
-2 3 20 cc00ff
-1 3 20 cc00ff
-16 4 20 cc00ff
-15 4 20 cc00ff
-14 4 20 cc00ff
-13 4 20 cc00ff
-12 4 20 cc00ff
-11 4 20 cc00ff
-10 4 20 cc00ff
-9 4 20 cc00ff
-8 4 20 cc00ff
-7 4 20 cc00ff
-6 4 20 cc00ff
-5 4 20 cc00ff
-4 4 20 cc00ff
-3 4 20 cc00ff
-2 4 20 cc00ff
-1 4 20 cc00ff
-16 15 20 0000ff
-16 4 21 cc00ff
-15 4 21 cc00ff
-14 4 21 cc00ff
-13 4 21 cc00ff
-12 4 21 cc00ff
-11 4 21 cc00ff
-10 4 21 cc00ff
-9 4 21 cc00ff
-8 4 21 cc00ff
-7 4 21 cc00ff
-6 4 21 cc00ff
-5 4 21 cc00ff
-4 4 21 cc00ff
-3 4 21 cc00ff
-2 4 21 cc00ff
-1 4 21 cc00ff
-16 5 21 cc00ff
-15 5 21 cc00ff
-14 5 21 cc00ff
-13 5 21 cc00ff
-12 5 21 cc00ff
-11 5 21 cc00ff
-10 5 21 cc00ff
-9 5 21 cc00ff
-8 5 21 cc00ff
-7 5 21 cc00ff
-6 5 21 cc00ff
-5 5 21 cc00ff
-4 5 21 cc00ff
-3 5 21 cc00ff
-2 5 21 cc00ff
-1 5 21 cc00ff
-16 15 21 0000ff
-16 5 22 cc00ff
-15 5 22 cc00ff
-14 5 22 cc00ff
-13 5 22 cc00ff
-12 5 22 cc00ff
-11 5 22 cc00ff
-10 5 22 cc00ff
-9 5 22 cc00ff
-8 5 22 cc00ff
-7 5 22 cc00ff
-6 5 22 cc00ff
-5 5 22 cc00ff
-4 5 22 cc00ff
-3 5 22 cc00ff
-2 5 22 cc00ff
-1 5 22 cc00ff
-16 6 22 cc00ff
-15 6 22 cc00ff
-14 6 22 cc00ff
-13 6 22 cc00ff
-12 6 22 cc00ff
-11 6 22 cc00ff
-10 6 22 cc00ff
-9 6 22 cc00ff
-8 6 22 cc00ff
-7 6 22 cc00ff
-6 6 22 cc00ff
-5 6 22 cc00ff
-4 6 22 cc00ff
-3 6 22 cc00ff
-2 6 22 cc00ff
-1 6 22 cc00ff
-16 15 22 0000ff
-16 6 23 cc00ff
-15 6 23 cc00ff
-14 6 23 cc00ff
-13 6 23 cc00ff
-12 6 23 cc00ff
-11 6 23 cc00ff
-10 6 23 cc00ff
-9 6 23 cc00ff
-8 6 23 cc00ff
-7 6 23 cc00ff
-6 6 23 cc00ff
-5 6 23 cc00ff
-4 6 23 cc00ff
-3 6 23 cc00ff
-2 6 23 cc00ff
-1 6 23 cc00ff
-16 7 23 cc00ff
-15 7 23 cc00ff
-14 7 23 cc00ff
-13 7 23 cc00ff
-12 7 23 cc00ff
-11 7 23 cc00ff
-10 7 23 cc00ff
-9 7 23 cc00ff
-8 7 23 cc00ff
-7 7 23 cc00ff
-6 7 23 cc00ff
-5 7 23 cc00ff
-4 7 23 cc00ff
-3 7 23 cc00ff
-2 7 23 cc00ff
-1 7 23 cc00ff
-16 15 23 0000ff
-16 7 24 cc00ff
-15 7 24 cc00ff
-14 7 24 cc00ff
-13 7 24 cc00ff
-12 7 24 cc00ff
-11 7 24 cc00ff
-10 7 24 cc00ff
-9 7 24 cc00ff
-8 7 24 cc00ff
-7 7 24 cc00ff
-6 7 24 cc00ff
-5 7 24 cc00ff
-4 7 24 cc00ff
-3 7 24 cc00ff
-2 7 24 cc00ff
-1 7 24 cc00ff
-16 8 24 cc00ff
-15 8 24 cc00ff
-14 8 24 cc00ff
-13 8 24 cc00ff
-12 8 24 cc00ff
-11 8 24 cc00ff
-10 8 24 cc00ff
-9 8 24 cc00ff
-8 8 24 cc00ff
-7 8 24 cc00ff
-6 8 24 cc00ff
-5 8 24 cc00ff
-4 8 24 cc00ff
-3 8 24 cc00ff
-2 8 24 cc00ff
-1 8 24 cc00ff
-16 15 24 0000ff
-16 8 25 cc00ff
-15 8 25 cc00ff
-14 8 25 cc00ff
-13 8 25 cc00ff
-12 8 25 cc00ff
-11 8 25 cc00ff
-10 8 25 cc00ff
-9 8 25 cc00ff
-8 8 25 cc00ff
-7 8 25 cc00ff
-6 8 25 cc00ff
-5 8 25 cc00ff
-4 8 25 cc00ff
-3 8 25 cc00ff
-2 8 25 cc00ff
-1 8 25 cc00ff
-16 9 25 cc00ff
-15 9 25 cc00ff
-14 9 25 cc00ff
-13 9 25 cc00ff
-12 9 25 cc00ff
-11 9 25 cc00ff
-10 9 25 cc00ff
-9 9 25 cc00ff
-8 9 25 cc00ff
-7 9 25 cc00ff
-6 9 25 cc00ff
-5 9 25 cc00ff
-4 9 25 cc00ff
-3 9 25 cc00ff
-2 9 25 cc00ff
-1 9 25 cc00ff
-16 15 25 0000ff
-16 9 26 cc00ff
-15 9 26 cc00ff
-14 9 26 cc00ff
-13 9 26 cc00ff
-12 9 26 cc00ff
-11 9 26 cc00ff
-10 9 26 cc00ff
-9 9 26 cc00ff
-8 9 26 cc00ff
-7 9 26 cc00ff
-6 9 26 cc00ff
-5 9 26 cc00ff
-4 9 26 cc00ff
-3 9 26 cc00ff
-2 9 26 cc00ff
-1 9 26 cc00ff
-16 10 26 cc00ff
-15 10 26 cc00ff
-14 10 26 cc00ff
-13 10 26 cc00ff
-12 10 26 cc00ff
-11 10 26 cc00ff
-10 10 26 cc00ff
-9 10 26 cc00ff
-8 10 26 cc00ff
-7 10 26 cc00ff
-6 10 26 cc00ff
-5 10 26 cc00ff
-4 10 26 cc00ff
-3 10 26 cc00ff
-2 10 26 cc00ff
-1 10 26 cc00ff
-16 15 26 0000ff
-16 10 27 cc00ff
-15 10 27 cc00ff
-14 10 27 cc00ff
-13 10 27 cc00ff
-12 10 27 cc00ff
-11 10 27 cc00ff
-10 10 27 cc00ff
-9 10 27 cc00ff
-8 10 27 cc00ff
-7 10 27 cc00ff
-6 10 27 cc00ff
-5 10 27 cc00ff
-4 10 27 cc00ff
-3 10 27 cc00ff
-2 10 27 cc00ff
-1 10 27 cc00ff
-16 11 27 cc00ff
-15 11 27 cc00ff
-14 11 27 cc00ff
-13 11 27 cc00ff
-12 11 27 cc00ff
-11 11 27 cc00ff
-10 11 27 cc00ff
-9 11 27 cc00ff
-8 11 27 cc00ff
-7 11 27 cc00ff
-6 11 27 cc00ff
-5 11 27 cc00ff
-4 11 27 cc00ff
-3 11 27 cc00ff
-2 11 27 cc00ff
-1 11 27 cc00ff
-16 15 27 0000ff
-16 11 28 cc00ff
-15 11 28 cc00ff
-14 11 28 cc00ff
-13 11 28 cc00ff
-12 11 28 cc00ff
-11 11 28 cc00ff
-10 11 28 cc00ff
-9 11 28 cc00ff
-8 11 28 cc00ff
-7 11 28 cc00ff
-6 11 28 cc00ff
-5 11 28 cc00ff
-4 11 28 cc00ff
-3 11 28 cc00ff
-2 11 28 cc00ff
-1 11 28 cc00ff
-16 12 28 cc00ff
-15 12 28 cc00ff
-14 12 28 cc00ff
-13 12 28 cc00ff
-12 12 28 cc00ff
-11 12 28 cc00ff
-10 12 28 cc00ff
-9 12 28 cc00ff
-8 12 28 cc00ff
-7 12 28 cc00ff
-6 12 28 cc00ff
-5 12 28 cc00ff
-4 12 28 cc00ff
-3 12 28 cc00ff
-2 12 28 cc00ff
-1 12 28 cc00ff
-16 15 28 0000ff
-16 12 29 cc00ff
-15 12 29 cc00ff
-14 12 29 cc00ff
-13 12 29 cc00ff
-12 12 29 cc00ff
-11 12 29 cc00ff
-10 12 29 cc00ff
-9 12 29 cc00ff
-8 12 29 cc00ff
-7 12 29 cc00ff
-6 12 29 cc00ff
-5 12 29 cc00ff
-4 12 29 cc00ff
-3 12 29 cc00ff
-2 12 29 cc00ff
-1 12 29 cc00ff
-16 13 29 cc00ff
-15 13 29 cc00ff
-14 13 29 cc00ff
-13 13 29 cc00ff
-12 13 29 cc00ff
-11 13 29 cc00ff
-10 13 29 cc00ff
-9 13 29 cc00ff
-8 13 29 cc00ff
-7 13 29 cc00ff
-6 13 29 cc00ff
-5 13 29 cc00ff
-4 13 29 cc00ff
-3 13 29 cc00ff
-2 13 29 cc00ff
-1 13 29 cc00ff
-16 15 29 0000ff
-16 13 30 cc00ff
-15 13 30 cc00ff
-14 13 30 cc00ff
-13 13 30 cc00ff
-12 13 30 cc00ff
-11 13 30 cc00ff
-10 13 30 cc00ff
-9 13 30 cc00ff
-8 13 30 cc00ff
-7 13 30 cc00ff
-6 13 30 cc00ff
-5 13 30 cc00ff
-4 13 30 cc00ff
-3 13 30 cc00ff
-2 13 30 cc00ff
-1 13 30 cc00ff
-16 14 30 cc00ff
-15 14 30 cc00ff
-14 14 30 cc00ff
-13 14 30 cc00ff
-12 14 30 cc00ff
-11 14 30 cc00ff
-10 14 30 cc00ff
-9 14 30 cc00ff
-8 14 30 cc00ff
-7 14 30 cc00ff
-6 14 30 cc00ff
-5 14 30 cc00ff
-4 14 30 cc00ff
-3 14 30 cc00ff
-2 14 30 cc00ff
-1 14 30 cc00ff
-16 0 31 00ff00
-16 1 31 00ff00
-16 2 31 00ff00
-16 3 31 00ff00
-16 4 31 00ff00
-16 5 31 00ff00
-16 6 31 00ff00
-16 7 31 00ff00
-16 8 31 00ff00
-16 9 31 00ff00
-16 10 31 00ff00
-16 11 31 00ff00
-16 12 31 00ff00
-16 13 31 00ff00
-16 14 31 00ff00
-16 15 31 000000
-15 15 31 ff0000
-14 15 31 ff0000
-13 15 31 ff0000
-12 15 31 ff0000
-11 15 31 ff0000
-10 15 31 ff0000
-9 15 31 ff0000
-8 15 31 ff0000
-7 15 31 ff0000
-6 15 31 ff0000
-5 15 31 ff0000
-4 15 31 ff0000
-3 15 31 ff0000
-2 15 31 ff0000
-1 15 31 ff0000
-16 -16 16 0000ff
-16 -1 16 cc00ff
-15 -1 16 cc00ff
-14 -1 16 cc00ff
-13 -1 16 cc00ff
-12 -1 16 cc00ff
-11 -1 16 cc00ff
-10 -1 16 cc00ff
-9 -1 16 cc00ff
-8 -1 16 cc00ff
-7 -1 16 cc00ff
-6 -1 16 cc00ff
-5 -1 16 cc00ff
-4 -1 16 cc00ff
-3 -1 16 cc00ff
-2 -1 16 cc00ff
-1 -1 16 cc00ff
-16 -16 17 0000ff
-16 -16 18 0000ff
-16 -16 19 0000ff
-16 -16 20 0000ff
-16 -16 21 0000ff
-16 -16 22 0000ff
-16 -16 23 0000ff
-16 -16 24 0000ff
-16 -16 25 0000ff
-16 -16 26 0000ff
-16 -16 27 0000ff
-16 -16 28 0000ff
-16 -16 29 0000ff
-16 -16 30 0000ff
-16 -16 31 000000
-15 -16 31 ff0000
-14 -16 31 ff0000
-13 -16 31 ff0000
-12 -16 31 ff0000
-11 -16 31 ff0000
-10 -16 31 ff0000
-9 -16 31 ff0000
-8 -16 31 ff0000
-7 -16 31 ff0000
-6 -16 31 ff0000
-5 -16 31 ff0000
-4 -16 31 ff0000
-3 -16 31 ff0000
-2 -16 31 ff0000
-1 -16 31 ff0000
-16 -15 31 00ff00
-16 -14 31 00ff00
-16 -13 31 00ff00
-16 -12 31 00ff00
-16 -11 31 00ff00
-16 -10 31 00ff00
-16 -9 31 00ff00
-16 -8 31 00ff00
-16 -7 31 00ff00
-16 -6 31 00ff00
-16 -5 31 00ff00
-16 -4 31 00ff00
-16 -3 31 00ff00
-16 -2 31 00ff00
-16 -1 31 00ff00
0 0 16 cc00ff
1 0 16 cc00ff
2 0 16 cc00ff
3 0 16 cc00ff
4 0 16 cc00ff
5 0 16 cc00ff
6 0 16 cc00ff
7 0 16 cc00ff
8 0 16 cc00ff
9 0 16 cc00ff
10 0 16 cc00ff
11 0 16 cc00ff
12 0 16 cc00ff
13 0 16 cc00ff
14 0 16 cc00ff
15 0 16 cc00ff
15 15 16 0000ff
0 0 17 cc00ff
1 0 17 cc00ff
2 0 17 cc00ff
3 0 17 cc00ff
4 0 17 cc00ff
5 0 17 cc00ff
6 0 17 cc00ff
7 0 17 cc00ff
8 0 17 cc00ff
9 0 17 cc00ff
10 0 17 cc00ff
11 0 17 cc00ff
12 0 17 cc00ff
13 0 17 cc00ff
14 0 17 cc00ff
15 0 17 cc00ff
0 1 17 cc00ff
1 1 17 cc00ff
2 1 17 cc00ff
3 1 17 cc00ff
4 1 17 cc00ff
5 1 17 cc00ff
6 1 17 cc00ff
7 1 17 cc00ff
8 1 17 cc00ff
9 1 17 cc00ff
10 1 17 cc00ff
11 1 17 cc00ff
12 1 17 cc00ff
13 1 17 cc00ff
14 1 17 cc00ff
15 1 17 cc00ff
15 15 17 0000ff
0 1 18 cc00ff
1 1 18 cc00ff
2 1 18 cc00ff
3 1 18 cc00ff
4 1 18 cc00ff
5 1 18 cc00ff
6 1 18 cc00ff
7 1 18 cc00ff
8 1 18 cc00ff
9 1 18 cc00ff
10 1 18 cc00ff
11 1 18 cc00ff
12 1 18 cc00ff
13 1 18 cc00ff
14 1 18 cc00ff
15 1 18 cc00ff
0 2 18 cc00ff
1 2 18 cc00ff
2 2 18 cc00ff
3 2 18 cc00ff
4 2 18 cc00ff
5 2 18 cc00ff
6 2 18 cc00ff
7 2 18 cc00ff
8 2 18 cc00ff
9 2 18 cc00ff
10 2 18 cc00ff
11 2 18 cc00ff
12 2 18 cc00ff
13 2 18 cc00ff
14 2 18 cc00ff
15 2 18 cc00ff
15 15 18 0000ff
0 2 19 cc00ff
1 2 19 cc00ff
2 2 19 cc00ff
3 2 19 cc00ff
4 2 19 cc00ff
5 2 19 cc00ff
6 2 19 cc00ff
7 2 19 cc00ff
8 2 19 cc00ff
9 2 19 cc00ff
10 2 19 cc00ff
11 2 19 cc00ff
12 2 19 cc00ff
13 2 19 cc00ff
14 2 19 cc00ff
15 2 19 cc00ff
0 3 19 cc00ff
1 3 19 cc00ff
2 3 19 cc00ff
3 3 19 cc00ff
4 3 19 cc00ff
5 3 19 cc00ff
6 3 19 cc00ff
7 3 19 cc00ff
8 3 19 cc00ff
9 3 19 cc00ff
10 3 19 cc00ff
11 3 19 cc00ff
12 3 19 cc00ff
13 3 19 cc00ff
14 3 19 cc00ff
15 3 19 cc00ff
15 15 19 0000ff
0 3 20 cc00ff
1 3 20 cc00ff
2 3 20 cc00ff
3 3 20 cc00ff
4 3 20 cc00ff
5 3 20 cc00ff
6 3 20 cc00ff
7 3 20 cc00ff
8 3 20 cc00ff
9 3 20 cc00ff
10 3 20 cc00ff
11 3 20 cc00ff
12 3 20 cc00ff
13 3 20 cc00ff
14 3 20 cc00ff
15 3 20 cc00ff
0 4 20 cc00ff
1 4 20 cc00ff
2 4 20 cc00ff
3 4 20 cc00ff
4 4 20 cc00ff
5 4 20 cc00ff
6 4 20 cc00ff
7 4 20 cc00ff
8 4 20 cc00ff
9 4 20 cc00ff
10 4 20 cc00ff
11 4 20 cc00ff
12 4 20 cc00ff
13 4 20 cc00ff
14 4 20 cc00ff
15 4 20 cc00ff
15 15 20 0000ff
0 4 21 cc00ff
1 4 21 cc00ff
2 4 21 cc00ff
3 4 21 cc00ff
4 4 21 cc00ff
5 4 21 cc00ff
6 4 21 cc00ff
7 4 21 cc00ff
8 4 21 cc00ff
9 4 21 cc00ff
10 4 21 cc00ff
11 4 21 cc00ff
12 4 21 cc00ff
13 4 21 cc00ff
14 4 21 cc00ff
15 4 21 cc00ff
0 5 21 cc00ff
1 5 21 cc00ff
2 5 21 cc00ff
3 5 21 cc00ff
4 5 21 cc00ff
5 5 21 cc00ff
6 5 21 cc00ff
7 5 21 cc00ff
8 5 21 cc00ff
9 5 21 cc00ff
10 5 21 cc00ff
11 5 21 cc00ff
12 5 21 cc00ff
13 5 21 cc00ff
14 5 21 cc00ff
15 5 21 cc00ff
15 15 21 0000ff
0 5 22 cc00ff
1 5 22 cc00ff
2 5 22 cc00ff
3 5 22 cc00ff
4 5 22 cc00ff
5 5 22 cc00ff
6 5 22 cc00ff
7 5 22 cc00ff
8 5 22 cc00ff
9 5 22 cc00ff
10 5 22 cc00ff
11 5 22 cc00ff
12 5 22 cc00ff
13 5 22 cc00ff
14 5 22 cc00ff
15 5 22 cc00ff
0 6 22 cc00ff
1 6 22 cc00ff
2 6 22 cc00ff
3 6 22 cc00ff
4 6 22 cc00ff
5 6 22 cc00ff
6 6 22 cc00ff
7 6 22 cc00ff
8 6 22 cc00ff
9 6 22 cc00ff
10 6 22 cc00ff
11 6 22 cc00ff
12 6 22 cc00ff
13 6 22 cc00ff
14 6 22 cc00ff
15 6 22 cc00ff
15 15 22 0000ff
0 6 23 cc00ff
1 6 23 cc00ff
2 6 23 cc00ff
3 6 23 cc00ff
4 6 23 cc00ff
5 6 23 cc00ff
6 6 23 cc00ff
7 6 23 cc00ff
8 6 23 cc00ff
9 6 23 cc00ff
10 6 23 cc00ff
11 6 23 cc00ff
12 6 23 cc00ff
13 6 23 cc00ff
14 6 23 cc00ff
15 6 23 cc00ff
0 7 23 cc00ff
1 7 23 cc00ff
2 7 23 cc00ff
3 7 23 cc00ff
4 7 23 cc00ff
5 7 23 cc00ff
6 7 23 cc00ff
7 7 23 cc00ff
8 7 23 cc00ff
9 7 23 cc00ff
10 7 23 cc00ff
11 7 23 cc00ff
12 7 23 cc00ff
13 7 23 cc00ff
14 7 23 cc00ff
15 7 23 cc00ff
15 15 23 0000ff
0 7 24 cc00ff
1 7 24 cc00ff
2 7 24 cc00ff
3 7 24 cc00ff
4 7 24 cc00ff
5 7 24 cc00ff
6 7 24 cc00ff
7 7 24 cc00ff
8 7 24 cc00ff
9 7 24 cc00ff
10 7 24 cc00ff
11 7 24 cc00ff
12 7 24 cc00ff
13 7 24 cc00ff
14 7 24 cc00ff
15 7 24 cc00ff
0 8 24 cc00ff
1 8 24 cc00ff
2 8 24 cc00ff
3 8 24 cc00ff
4 8 24 cc00ff
5 8 24 cc00ff
6 8 24 cc00ff
7 8 24 cc00ff
8 8 24 cc00ff
9 8 24 cc00ff
10 8 24 cc00ff
11 8 24 cc00ff
12 8 24 cc00ff
13 8 24 cc00ff
14 8 24 cc00ff
15 8 24 cc00ff
15 15 24 0000ff
0 8 25 cc00ff
1 8 25 cc00ff
2 8 25 cc00ff
3 8 25 cc00ff
4 8 25 cc00ff
5 8 25 cc00ff
6 8 25 cc00ff
7 8 25 cc00ff
8 8 25 cc00ff
9 8 25 cc00ff
10 8 25 cc00ff
11 8 25 cc00ff
12 8 25 cc00ff
13 8 25 cc00ff
14 8 25 cc00ff
15 8 25 cc00ff
0 9 25 cc00ff
1 9 25 cc00ff
2 9 25 cc00ff
3 9 25 cc00ff
4 9 25 cc00ff
5 9 25 cc00ff
6 9 25 cc00ff
7 9 25 cc00ff
8 9 25 cc00ff
9 9 25 cc00ff
10 9 25 cc00ff
11 9 25 cc00ff
12 9 25 cc00ff
13 9 25 cc00ff
14 9 25 cc00ff
15 9 25 cc00ff
15 15 25 0000ff
0 9 26 cc00ff
1 9 26 cc00ff
2 9 26 cc00ff
3 9 26 cc00ff
4 9 26 cc00ff
5 9 26 cc00ff
6 9 26 cc00ff
7 9 26 cc00ff
8 9 26 cc00ff
9 9 26 cc00ff
10 9 26 cc00ff
11 9 26 cc00ff
12 9 26 cc00ff
13 9 26 cc00ff
14 9 26 cc00ff
15 9 26 cc00ff
0 10 26 cc00ff
1 10 26 cc00ff
2 10 26 cc00ff
3 10 26 cc00ff
4 10 26 cc00ff
5 10 26 cc00ff
6 10 26 cc00ff
7 10 26 cc00ff
8 10 26 cc00ff
9 10 26 cc00ff
10 10 26 cc00ff
11 10 26 cc00ff
12 10 26 cc00ff
13 10 26 cc00ff
14 10 26 cc00ff
15 10 26 cc00ff
15 15 26 0000ff
0 10 27 cc00ff
1 10 27 cc00ff
2 10 27 cc00ff
3 10 27 cc00ff
4 10 27 cc00ff
5 10 27 cc00ff
6 10 27 cc00ff
7 10 27 cc00ff
8 10 27 cc00ff
9 10 27 cc00ff
10 10 27 cc00ff
11 10 27 cc00ff
12 10 27 cc00ff
13 10 27 cc00ff
14 10 27 cc00ff
15 10 27 cc00ff
0 11 27 cc00ff
1 11 27 cc00ff
2 11 27 cc00ff
3 11 27 cc00ff
4 11 27 cc00ff
5 11 27 cc00ff
6 11 27 cc00ff
7 11 27 cc00ff
8 11 27 cc00ff
9 11 27 cc00ff
10 11 27 cc00ff
11 11 27 cc00ff
12 11 27 cc00ff
13 11 27 cc00ff
14 11 27 cc00ff
15 11 27 cc00ff
15 15 27 0000ff
0 11 28 cc00ff
1 11 28 cc00ff
2 11 28 cc00ff
3 11 28 cc00ff
4 11 28 cc00ff
5 11 28 cc00ff
6 11 28 cc00ff
7 11 28 cc00ff
8 11 28 cc00ff
9 11 28 cc00ff
10 11 28 cc00ff
11 11 28 cc00ff
12 11 28 cc00ff
13 11 28 cc00ff
14 11 28 cc00ff
15 11 28 cc00ff
0 12 28 cc00ff
1 12 28 cc00ff
2 12 28 cc00ff
3 12 28 cc00ff
4 12 28 cc00ff
5 12 28 cc00ff
6 12 28 cc00ff
7 12 28 cc00ff
8 12 28 cc00ff
9 12 28 cc00ff
10 12 28 cc00ff
11 12 28 cc00ff
12 12 28 cc00ff
13 12 28 cc00ff
14 12 28 cc00ff
15 12 28 cc00ff
15 15 28 0000ff
0 12 29 cc00ff
1 12 29 cc00ff
2 12 29 cc00ff
3 12 29 cc00ff
4 12 29 cc00ff
5 12 29 cc00ff
6 12 29 cc00ff
7 12 29 cc00ff
8 12 29 cc00ff
9 12 29 cc00ff
10 12 29 cc00ff
11 12 29 cc00ff
12 12 29 cc00ff
13 12 29 cc00ff
14 12 29 cc00ff
15 12 29 cc00ff
0 13 29 cc00ff
1 13 29 cc00ff
2 13 29 cc00ff
3 13 29 cc00ff
4 13 29 cc00ff
5 13 29 cc00ff
6 13 29 cc00ff
7 13 29 cc00ff
8 13 29 cc00ff
9 13 29 cc00ff
10 13 29 cc00ff
11 13 29 cc00ff
12 13 29 cc00ff
13 13 29 cc00ff
14 13 29 cc00ff
15 13 29 cc00ff
15 15 29 0000ff
0 13 30 cc00ff
1 13 30 cc00ff
2 13 30 cc00ff
3 13 30 cc00ff
4 13 30 cc00ff
5 13 30 cc00ff
6 13 30 cc00ff
7 13 30 cc00ff
8 13 30 cc00ff
9 13 30 cc00ff
10 13 30 cc00ff
11 13 30 cc00ff
12 13 30 cc00ff
13 13 30 cc00ff
14 13 30 cc00ff
15 13 30 cc00ff
0 14 30 cc00ff
1 14 30 cc00ff
2 14 30 cc00ff
3 14 30 cc00ff
4 14 30 cc00ff
5 14 30 cc00ff
6 14 30 cc00ff
7 14 30 cc00ff
8 14 30 cc00ff
9 14 30 cc00ff
10 14 30 cc00ff
11 14 30 cc00ff
12 14 30 cc00ff
13 14 30 cc00ff
14 14 30 cc00ff
15 14 30 cc00ff
15 15 30 0000ff
15 0 31 00ff00
15 1 31 00ff00
15 2 31 00ff00
15 3 31 00ff00
15 4 31 00ff00
15 5 31 00ff00
15 6 31 00ff00
15 7 31 00ff00
15 8 31 00ff00
15 9 31 00ff00
15 10 31 00ff00
15 11 31 00ff00
15 12 31 00ff00
15 13 31 00ff00
15 14 31 00ff00
0 15 31 ff0000
1 15 31 ff0000
2 15 31 ff0000
3 15 31 ff0000
4 15 31 ff0000
5 15 31 ff0000
6 15 31 ff0000
7 15 31 ff0000
8 15 31 ff0000
9 15 31 ff0000
10 15 31 ff0000
11 15 31 ff0000
12 15 31 ff0000
13 15 31 ff0000
14 15 31 ff0000
15 15 31 000000
15 -16 16 0000ff
0 -1 16 cc00ff
1 -1 16 cc00ff
2 -1 16 cc00ff
3 -1 16 cc00ff
4 -1 16 cc00ff
5 -1 16 cc00ff
6 -1 16 cc00ff
7 -1 16 cc00ff
8 -1 16 cc00ff
9 -1 16 cc00ff
10 -1 16 cc00ff
11 -1 16 cc00ff
12 -1 16 cc00ff
13 -1 16 cc00ff
14 -1 16 cc00ff
15 -1 16 cc00ff
15 -16 17 0000ff
15 -16 18 0000ff
15 -16 19 0000ff
15 -16 20 0000ff
15 -16 21 0000ff
15 -16 22 0000ff
15 -16 23 0000ff
15 -16 24 0000ff
15 -16 25 0000ff
15 -16 26 0000ff
15 -16 27 0000ff
15 -16 28 0000ff
15 -16 29 0000ff
15 -16 30 0000ff
0 -16 31 ff0000
1 -16 31 ff0000
2 -16 31 ff0000
3 -16 31 ff0000
4 -16 31 ff0000
5 -16 31 ff0000
6 -16 31 ff0000
7 -16 31 ff0000
8 -16 31 ff0000
9 -16 31 ff0000
10 -16 31 ff0000
11 -16 31 ff0000
12 -16 31 ff0000
13 -16 31 ff0000
14 -16 31 ff0000
15 -16 31 000000
15 -15 31 00ff00
15 -14 31 00ff00
15 -13 31 00ff00
15 -12 31 00ff00
15 -11 31 00ff00
15 -10 31 00ff00
15 -9 31 00ff00
15 -8 31 00ff00
15 -7 31 00ff00
15 -6 31 00ff00
15 -5 31 00ff00
15 -4 31 00ff00
15 -3 31 00ff00
15 -2 31 00ff00
15 -1 31 00ff00
